Workbook

Sheet Materials
A1: Material code | B1: Description | C1: Collection | D1: Supplier | E1: Supplier code | F1: Category | G1: Composition | H1: Weight | I1: Width / skin size | J1: Price | K1: Currency | L1: Price unit | M1: MOQ | N1: Lead time (wks) | O1: Country of origin | P1: Certification | Q1: Status | R1: Created by | S1: Created on | T1: Last modified | U1: Comments | V1: Colours ordered (calc)
A2: FAB-26W-1001 | B2: Double-face wool cloth | C2: FW26 | D2: Lanificio Ardesia | E2: SUP-0112 | F2: Wool | G2: 90% WV 10% WS | H2: 556 g/m² | I2: 150 cm | J2: 86.5 | K2: EUR | L2: €/m | M2: 300 | N2: 3 | O2: Italy | P2: No certification | Q2: On hold | R2: L. Martín | S2: 45978 | T2: 46047 | U2: Supplier capacity issue | V2: =COUNTIFS(Colours!$A$2:$A$742,$A2,Colours!$D$2:$D$742,"Ordered") -> 0
A3: FAB-26W-1005 | B3: Waxed cotton | C3: FW26 | D3: Kōzan Weaving | E3: SUP-0311 | F3: Technical | G3: 100% PA | H3: 163 g/m² | I3: 145 cm | J3: 42.1 | K3: EUR | L3: €/m | M3: 20 | N3: 11 | O3: Japan | P3: GRS | Q3: Approved | R3: V. Roux | S3: 45993 | T3: 46071 | V3: =COUNTIFS(Colours!$A$2:$A$742,$A3,Colours!$D$2:$D$742,"Ordered") -> 1
A4: FAB-26W-1010 | B4: Cotton poplin | C4: FW26 | D4: Tessitura Morano | E4: SUP-0147 | F4: Cotton | G4: 100% CO (organic) | H4: 389 g/m² | I4: 145 cm | J4: 12.39 | K4: EUR | L4: €/m | M4: 300 | N4: 14 | P4: GOTS | Q4: Approved | R4: C. Ibáñez | S4: 45994 | T4: 46105 | U4: Exclusive to Loewe | V4: =COUNTIFS(Colours!$A$2:$A$742,$A4,Colours!$D$2:$D$742,"Ordered") -> 1
A5: FAB-26W-1012 | B5: Silk satin | C5: FW26 | D5: Soieries Bellecour | E5: SUP-0174 | F5: Silk | G5: 100% SE | H5: 139 g/m² | I5: 145 cm | J5: 103.15 | K5: EUR | L5: €/m | M5: 100 | N5: 6 | O5: France | P5: No certification | Q5: In development | R5: C. Ibáñez | S5: 45974 | T5: 46110 | V5: =COUNTIFS(Colours!$A$2:$A$742,$A5,Colours!$D$2:$D$742,"Ordered") -> 1
A6: FAB-26W-1019 | B6: Washed linen | C6: FW26 | D6: Linificio Brianza | E6: SUP-0126 | F6: Linen | G6: 100% LI | H6: 234 g/m² | I6: 145 cm | J6: 15.41 | K6: EUR | L6: €/m | M6: 50 | N6: 6 | O6: Italy | P6: European Flax | Q6: In development | R6: C. Ibáñez | S6: 45972 | T6: 46097 | V6: =COUNTIFS(Colours!$A$2:$A$742,$A6,Colours!$D$2:$D$742,"Ordered") -> 2
A7: FAB-26W-1024 | B7: Cotton poplin | C7: FW26 | D7: Tessitura Morano | E7: SUP-0147 | F7: Cotton | G7: 98% CO 2% EA | H7: 110 g/m² | I7: 145 cm | J7: 30.92 | K7: EUR | L7: €/m | M7: 50 | N7: 7 | O7: Italy | P7: No certification | Q7: On hold | R7: A. Costa | S7: 45977 | T7: 46012 | U7: Waiting for lab dip | V7: =COUNTIFS(Colours!$A$2:$A$742,$A7,Colours!$D$2:$D$742,"Ordered") -> 2
A8: LEA-26W-1029 | B8: Glazed calfskin | C8: FW26 | D8: Curtidos Valle del Ubrique | E8: SUP-0021 | F8: Leather | G8: 100% lamb leather | H8: 0.7 mm | I8: 6-7 sqft | J8: 7.62 | K8: EUR | L8: €/sqft | M8: 500 | N8: 12 | O8: Spain | P8: LWG Gold | Q8: In development | R8: L. Martín | S8: 45989 | T8: 46052 | V8: =COUNTIFS(Colours!$A$2:$A$742,$A8,Colours!$D$2:$D$742,"Ordered") -> 1
A9: FAB-26W-1031 | B9: Double-face wool cloth | C9: FW26 | D9: Lanificio Ardesia | E9: SUP-0112 | F9: Wool | G9: 80% WV 20% PA | H9: 284 g/m² | I9: 148 cm | K9: EUR | L9: €/m | M9: 100 | N9: 13 | O9: Italy | Q9: Approved | R9: A. Costa | S9: 46020 | T9: 46152 | V9: =COUNTIFS(Colours!$A$2:$A$742,$A9,Colours!$D$2:$D$742,"Ordered") -> 1
A10: FAB-26W-1037 | B10: Viscose jersey | C10: FW26 | D10: Lanificio Ardesia | E10: SUP-0112 | F10: Jersey | G10: 95% CV 5% EA | H10: 255 g/m² | I10: 160 cm | J10: 56.8 | K10: EUR | L10: €/m | M10: 150 | O10: Italy | P10: RWS | Q10: On hold | R10: A. Costa | S10: 46011 | T10: 46130 | U10: Supplier capacity issue | V10: =COUNTIFS(Colours!$A$2:$A$742,$A10,Colours!$D$2:$D$742,"Ordered") -> 3
A11: FAB-26W-1038 | B11: Linen canvas | C11: FW26 | D11: Linificio Brianza | E11: SUP-0126 | F11: Linen | G11: 55% LI 45% CO | H11: 218 g/m² | I11: 145 cm | J11: 32.39 | K11: EUR | L11: €/m | M11: 300 | N11: 5 | O11: Italy | P11: No certification | Q11: Approved | R11: C. Ibáñez | S11: 46003 | T11: 46072 | V11: =COUNTIFS(Colours!$A$2:$A$742,$A11,Colours!$D$2:$D$742,"Ordered") -> 2
A12: LEA-26W-1040 | B12: Suede goatskin | C12: FW26 | D12: Conceria Valdarno | E12: SUP-0058 | F12: Leather | G12: 100% lamb leather | H12: 0.6 mm | I12: 5-6 sqft | J12: 9.97 | K12: EUR | L12: €/sqft | M12: 500 | N12: 9 | O12: Italy | P12: LWG Gold | Q12: In development | R12: V. Roux | S12: 46020 | T12: 46078 | U12: Exclusive to Loewe | V12: =COUNTIFS(Colours!$A$2:$A$742,$A12,Colours!$D$2:$D$742,"Ordered") -> 3
A13: LEA-26W-1044 | B13: Shearling lamb | C13: FW26 | D13: Pieles del Guadalete | E13: SUP-0039 | F13: Leather | G13: 100% lamb shearling | H13: 1.4 mm | I13: 7-9 sqft | J13: 10.81 | K13: EUR | L13: €/sqft | M13: 500 | N13: 3 | O13: Spain | Q13: In development | R13: V. Roux | S13: 46017 | T13: 46034 | V13: =COUNTIFS(Colours!$A$2:$A$742,$A13,Colours!$D$2:$D$742,"Ordered") -> 2
A14: LEA-26W-1045 | B14: Shearling lamb | C14: FW26 | D14: Pieles del Guadalete | E14: SUP-0039 | F14: Leather | G14: 100% lamb leather | H14: 1.3 mm | I14: 18-22 sqft | J14: 14.23 | K14: EUR | L14: €/sqft | M14: n/a | N14: 7 | O14: Spain | P14: LWG Gold | Q14: In development | R14: A. Costa | S14: 46018 | T14: 46106 | V14: =COUNTIFS(Colours!$A$2:$A$742,$A14,Colours!$D$2:$D$742,"Ordered") -> 2
A15: LEA-26W-1046 | B15: Calf box leather | C15: FW26 | D15: Pieles del Guadalete | E15: SUP-0039 | F15: Leather | G15: 100% goat leather | H15: 0.7 mm | I15: 5-6 sqft | J15: n/a | K15: EUR | L15: €/sqft | M15: 300 | N15: 9 | O15: Spain | P15: LWG Silver | Q15: Approved | R15: C. Ibáñez | S15: 46006 | T15: 46088 | U15: Strike-off approved | V15: =COUNTIFS(Colours!$A$2:$A$742,$A15,Colours!$D$2:$D$742,"Ordered") -> 0
A16: FAB-26W-1051 | B16: Wool melton | C16: FW26 | D16: Lanificio Ardesia | E16: SUP-0112 | F16: Wool | G16: 70% WV 30% WM | H16: 363 g/m² | I16: 152 cm | J16: 93.24 | K16: EUR | L16: €/m | M16: 50 | N16: 10 | O16: Italy | P16: No certification | Q16: Approved | R16: C. Ibáñez | S16: 45973 | T16: 46066 | U16: Top-up possible from FW25 leftovers | V16: =COUNTIFS(Colours!$A$2:$A$742,$A16,Colours!$D$2:$D$742,"Ordered") -> 0
A17: LEA-26W-1053 | B17: Nappa lambskin | C17: FW26 | D17: Curtidos Valle del Ubrique | E17: SUP-0021 | F17: Leather | G17: 100% lamb leather | H17: 1.1 mm | I17: 7-9 sqft | J17: 13.24 | K17: EUR | L17: €/sqft | M17: 500 | O17: Spain | P17: LWG Gold | Q17: In development | R17: A. Costa | S17: 46020 | T17: 46056 | V17: =COUNTIFS(Colours!$A$2:$A$742,$A17,Colours!$D$2:$D$742,"Ordered") -> 3
A18: FAB-26W-1057 | B18: Double-face wool cloth | C18: FW26 | D18: Lanificio Ardesia | E18: SUP-0112 | F18: Wool | G18: 100% WV | H18: 482 g/m² | K18: EUR | L18: €/m | M18: 150 | N18: 4 | O18: Italy | P18: RWS | Q18: In development | R18: C. Ibáñez | S18: 45997 | T18: 46026 | V18: =COUNTIFS(Colours!$A$2:$A$742,$A18,Colours!$D$2:$D$742,"Ordered") -> 2
A19: LEA-26W-1061 | B19: Shearling lamb | C19: FW26 | D19: Curtidos Valle del Ubrique | E19: SUP-0021 | F19: Leather | G19: 100% lamb leather | H19: 0.8 mm | I19: 6-7 sqft | J19: 15.91 | K19: EUR | L19: €/sqft | M19: 300 | N19: 10 | O19: Spain | P19: LWG Silver | Q19: Approved | R19: M. Duval | S19: 45984 | T19: 46083 | V19: =COUNTIFS(Colours!$A$2:$A$742,$A19,Colours!$D$2:$D$742,"Ordered") -> 2
A20: LEA-26W-1063 | B20: Nappa lambskin | C20: FW26 | D20: Curtidos Valle del Ubrique | E20: SUP-0021 | F20: Leather | G20: 100% calf leather | H20: 1.3 mm | I20: 7-9 sqft | J20: 13.89 | K20: EUR | L20: €/sqft | M20: 200 | N20: 4 | O20: Spain | P20: LWG Gold | Q20: In development | R20: C. Ibáñez | S20: 46019 | T20: 46153 | V20: =COUNTIFS(Colours!$A$2:$A$742,$A20,Colours!$D$2:$D$742,"Ordered") -> 1
A21: FAB-26W-1064 | B21: Merino rib | C21: FW26 | D21: Lanificio Ardesia | E21: SUP-0112 | F21: Jersey | G21: 92% SE 8% EA | H21: 184 g/m² | I21: 170 cm | J21: 34.85 | K21: EUR | L21: €/m | M21: 150 | N21: 3 | O21: Italy | P21: OEKO-TEX | Q21: Approved | R21: M. Duval | S21: 45998 | T21: 46084 | V21: =COUNTIFS(Colours!$A$2:$A$742,$A21,Colours!$D$2:$D$742,"Ordered") -> 3
A22: FAB-26W-1067 | B22: Cotton canvas | C22: FW26 | D22: Hilaturas Ebro | E22: SUP-0203 | F22: Cotton | G22: 98% CO 2% EA | H22: 209 g/m² | I22: 145 cm | J22: 33.12 | K22: EUR | L22: €/m | M22: 150 | N22: 14 | O22: Spain | P22: OEKO-TEX | Q22: On hold | R22: V. Roux | S22: 46016 | T22: 46051 | U22: Price to renegotiate | V22: =COUNTIFS(Colours!$A$2:$A$742,$A22,Colours!$D$2:$D$742,"Ordered") -> 3
A23: FAB-26W-1069 | B23: Cotton poplin | C23: FW26 | D23: Hilaturas Ebro | E23: SUP-0203 | F23: Cotton | G23: 100% CO | I23: 145 cm | K23: EUR | L23: €/m | M23: 100 | N23: 14 | O23: Spain | P23: No certification | Q23: In development | R23: M. Duval | S23: 45973 | T23: 46034 | V23: =COUNTIFS(Colours!$A$2:$A$742,$A23,Colours!$D$2:$D$742,"Ordered") -> 1
A24: LEA-26W-1075 | B24: Grained calfskin | C24: FW26 | D24: Pieles del Guadalete | E24: SUP-0039 | F24: Leather | G24: 100% lamb shearling | H24: 0.7 mm | I24: 5-6 sqft | J24: 10.66 | K24: EUR | L24: €/sqft | M24: 200 | N24: 14 | O24: Spain | Q24: On hold | R24: L. Martín | S24: 45975 | T24: 46103 | U24: Price to renegotiate | V24: =COUNTIFS(Colours!$A$2:$A$742,$A24,Colours!$D$2:$D$742,"Ordered") -> 1
A25: FAB-26W-1081 | B25: Merino rib | C25: FW26 | D25: Lanificio Ardesia | E25: SUP-0112 | F25: Jersey | G25: 100% CO | J25: 43.56 | K25: EUR | L25: €/m | M25: 20 | N25: 9 | O25: Italy | Q25: Approved | R25: M. Duval | S25: 45966 | T25: 46093 | V25: =COUNTIFS(Colours!$A$2:$A$742,$A25,Colours!$D$2:$D$742,"Ordered") -> 2
A26: LEA-26W-1082 | B26: Glazed calfskin | C26: FW26 | D26: Conceria Valdarno | E26: SUP-0058 | F26: Leather | G26: 100% lamb shearling | H26: 1.0 mm | J26: 9.55 | K26: EUR | L26: €/sqft | M26: 300 | N26: 14 | O26: Italy | P26: LWG Gold | Q26: In development | R26: V. Roux | S26: 46010 | T26: 46110 | V26: =COUNTIFS(Colours!$A$2:$A$742,$A26,Colours!$D$2:$D$742,"Ordered") -> 3
A27: LEA-26W-1089 | B27: Suede goatskin | C27: FW26 | D27: Conceria Valdarno | E27: SUP-0058 | F27: Leather | G27: 100% goat leather | H27: 0.8 mm | I27: 7-9 sqft | J27: 15.49 | K27: EUR | L27: €/sqft | M27: 500 | N27: 10 | O27: Italy | P27: LWG Gold | Q27: On hold | R27: L. Martín | S27: 46023 | T27: 46099 | U27: Supplier capacity issue | V27: =COUNTIFS(Colours!$A$2:$A$742,$A27,Colours!$D$2:$D$742,"Ordered") -> 1
A28: FAB-26W-1092 | B28: Organic cotton twill | C28: FW26 | D28: Kōzan Weaving | E28: SUP-0311 | F28: Cotton | G28: 98% CO 2% EA | H28: 297 g/m² | I28: 150 cm | J28: 27.8 | K28: EUR | L28: €/m | M28: 20 | N28: 13 | O28: Japan | P28: GOTS | Q28: On hold | R28: V. Roux | S28: 46011 | T28: 46048 | U28: Price to renegotiate | V28: =COUNTIFS(Colours!$A$2:$A$742,$A28,Colours!$D$2:$D$742,"Ordered") -> 1
A29: YRN-26W-1097 | B29: Mohair bouclé yarn | C29: FW26 | D29: Maglificio Orobico | E29: SUP-0188 | F29: Knit yarn | G29: 100% WO merino | H29: 9 Nm | I29: Cone (yarn) | J29: 66.52 | K29: EUR | L29: €/kg | M29: 150 | N29: n/a | O29: Italy | P29: No certification | Q29: Approved | R29: A. Costa | S29: 46016 | T29: 46092 | V29: =COUNTIFS(Colours!$A$2:$A$742,$A29,Colours!$D$2:$D$742,"Ordered") -> 3
A30: LEA-26W-1103 | B30: Shearling lamb | C30: FW26 | D30: Pieles del Guadalete | E30: SUP-0039 | F30: Leather | G30: 100% goat leather | H30: 1.3 mm | I30: 6-7 sqft | J30: 7.94 | K30: EUR | L30: €/sqft | M30: 300 | N30: 3 | O30: Spain | Q30: Approved | R30: L. Martín | S30: 45992 | T30: 46032 | V30: =COUNTIFS(Colours!$A$2:$A$742,$A30,Colours!$D$2:$D$742,"Ordered") -> 2
A31: FAB-26W-1110 | B31: Wool melton | C31: FW26 | D31: Lanificio Ardesia | E31: SUP-0112 | F31: Wool | G31: 100% WV | H31: 354 g/m² | I31: 152 cm | J31: 62.8 | K31: EUR | L31: €/m | M31: 300 | N31: 12 | O31: Italy | P31: RWS | Q31: Approved | R31: L. Martín | S31: 45987 | T31: 46035 | V31: =COUNTIFS(Colours!$A$2:$A$742,$A31,Colours!$D$2:$D$742,"Ordered") -> 3
A32: FAB-26W-1114 | B32: Wool melton | C32: FW26 | D32: Lanificio Ardesia | E32: SUP-0112 | F32: Wool | G32: 80% WV 20% PA | H32: 496 g/m² | I32: 148 cm | J32: 46.58 | K32: EUR | L32: €/m | M32: 150 | N32: 12 | O32: Italy | P32: RWS | Q32: Approved | R32: A. Costa | S32: 45972 | T32: 46050 | V32: =COUNTIFS(Colours!$A$2:$A$742,$A32,Colours!$D$2:$D$742,"Ordered") -> 0
A33: FAB-26W-1121 | B33: Silk satin | C33: FW26 | D33: Soieries Bellecour | E33: SUP-0174 | F33: Silk | G33: 70% CV 30% SE | H33: 104 g/m² | I33: 145 cm | J33: 92.57 | K33: EUR | L33: €/m | M33: 300 | N33: 4 | P33: No certification | Q33: On hold | R33: A. Costa | S33: 45968 | T33: 46018 | V33: =COUNTIFS(Colours!$A$2:$A$742,$A33,Colours!$D$2:$D$742,"Ordered") -> 3
A34: LEA-26W-1128 | B34: Calf box leather | C34: FW26 | D34: Pieles del Guadalete | E34: SUP-0039 | F34: Leather | G34: 100% goat leather | H34: 1.1 mm | I34: 5-6 sqft | J34: 6.29 | K34: EUR | L34: €/sqft | N34: n/a | O34: Spain | P34: LWG Gold | Q34: Approved | R34: A. Costa | S34: 45999 | T34: 46005 | V34: =COUNTIFS(Colours!$A$2:$A$742,$A34,Colours!$D$2:$D$742,"Ordered") -> 2
A35: FAB-26W-1133 | B35: Cashmere jersey | C35: FW26 | D35: Hilaturas Ebro | E35: SUP-0203 | F35: Jersey | G35: 95% CV 5% EA | H35: 267 g/m² | I35: 160 cm | J35: 77.6 | K35: EUR | L35: €/m | M35: 20 | O35: Spain | P35: No certification | Q35: On hold | R35: V. Roux | S35: 46023 | T35: 46031 | U35: Supplier capacity issue | V35: =COUNTIFS(Colours!$A$2:$A$742,$A35,Colours!$D$2:$D$742,"Ordered") -> 0
A36: LEA-26W-1137 | B36: Grained calfskin | C36: FW26 | D36: Curtidos Valle del Ubrique | E36: SUP-0021 | F36: Leather | G36: 100% lamb leather | H36: 0.7 mm | I36: 5-6 sqft | J36: 9.19 | K36: EUR | L36: €/sqft | M36: 300 | N36: 9 | O36: Spain | P36: LWG Gold | Q36: Approved | R36: C. Ibáñez | S36: 45983 | T36: 46054 | V36: =COUNTIFS(Colours!$A$2:$A$742,$A36,Colours!$D$2:$D$742,"Ordered") -> 5
A37: LEA-26W-1139 | B37: Calf box leather | C37: FW26 | D37: Pieles del Guadalete | E37: SUP-0039 | F37: Leather | G37: 100% calf leather | H37: 1.3 mm | I37: 18-22 sqft | J37: 11.4 | K37: EUR | L37: €/sqft | N37: 6 | O37: Spain | P37: LWG Gold | Q37: Approved | R37: A. Costa | S37: 45969 | T37: 46051 | V37: =COUNTIFS(Colours!$A$2:$A$742,$A37,Colours!$D$2:$D$742,"Ordered") -> 4
A38: FAB-26W-1143 | B38: Merino rib | C38: FW26 | D38: Lanificio Ardesia | E38: SUP-0112 | F38: Jersey | G38: 100% CO | H38: 176 g/m² | I38: 160 cm | K38: EUR | L38: €/m | M38: 150 | N38: 5 | O38: Italy | P38: RWS | Q38: On hold | R38: L. Martín | S38: 45966 | T38: 46081 | U38: Waiting for lab dip | V38: =COUNTIFS(Colours!$A$2:$A$742,$A38,Colours!$D$2:$D$742,"Ordered") -> 2
A39: FAB-26W-1145 | B39: Silk crêpe de chine | C39: FW26 | D39: Tessitura Morano | E39: SUP-0147 | F39: Silk | G39: 100% SE | H39: 115 g/m² | I39: 140 cm | J39: 103.41 | K39: EUR | L39: €/m | M39: 100 | N39: 8 | O39: Italy | P39: No certification | Q39: Approved | R39: M. Duval | S39: 45986 | T39: 46081 | V39: =COUNTIFS(Colours!$A$2:$A$742,$A39,Colours!$D$2:$D$742,"Ordered") -> 1
A40: YRN-26W-1149 | B40: Mohair bouclé yarn | C40: FW26 | D40: Maglificio Orobico | E40: SUP-0188 | F40: Knit yarn | G40: 100% CO | H40: 28 Nm | I40: Cone (yarn) | J40: 178.03 | K40: EUR | L40: €/kg | M40: 20 | N40: 5 | P40: GOTS | Q40: In development | R40: L. Martín | S40: 45986 | T40: 46073 | V40: =COUNTIFS(Colours!$A$2:$A$742,$A40,Colours!$D$2:$D$742,"Ordered") -> 3
...

Sheet Colours
A1: Material code | B1: Colour code | C1: Colour name | D1: Colour status | E1: Qty ordered | F1: Unit | G1: Order date
A2: FAB-26W-1001 | B2: 1001-CHC | C2: Chocolate | D2: Cancelled | F2: m
A3: FAB-26W-1005 | B3: 1005-CHC | C3: Chocolate | D3: Ordered | E3: 55 | F3: m | G3: 46009
A4: FAB-26W-1010 | B4: 1010-ECR | C4: Ecru | D4: Ordered | E4: 35 | F4: m | G4: 46055
A5: FAB-26W-1012 | B5: 1012-WHT | C5: Optic white | D5: Ordered | E5: 95 | F5: m | G5: 46003
A6: FAB-26W-1012 | B6: 1012-ECR | C6: Ecru | D6: Lab dip | F6: m
A7: FAB-26W-1019 | B7: 1019-GRY | C7: Grey melange | D7: Ordered | E7: 25 | F7: m | G7: 46026
A8: FAB-26W-1019 | B8: 1019-CHK | C8: Chalk | D8: Ordered | E8: 180 | F8: m | G8: 46015
A9: FAB-26W-1024 | B9: 1024-BRD | C9: Burgundy | D9: Ordered | E9: 120 | F9: m | G9: 46003
A10: FAB-26W-1024 | B10: 1024-GRY | C10: Grey melange | D10: Cancelled | F10: m
A11: FAB-26W-1024 | B11: 1024-SKY | C11: Sky blue | D11: Ordered | E11: 50 | F11: m | G11: 46026
A12: LEA-26W-1029 | B12: 1029-GRN | C12: Bottle green | D12: Ordered | E12: 90 | F12: sqft | G12: 46037
A13: FAB-26W-1031 | B13: 1031-WHT | C13: Optic white | D13: Cancelled | F13: m
A14: FAB-26W-1031 | B14: 1031-YLW | C14: Butter yellow | D14: Ordered | E14: 70 | F14: m | G14: 46073
A15: FAB-26W-1037 | B15: 1037-GRY | C15: Grey melange | D15: Lab dip | F15: m
A16: FAB-26W-1037 | B16: 1037-CML | C16: Camel | D16: Ordered | E16: 95 | F16: m | G16: 46025
A17: FAB-26W-1037 | B17: 1037-BLK | C17: Black | D17: Ordered | E17: 175 | F17: m | G17: 46028
A18: FAB-26W-1037 | B18: 1037-BRD | C18: Burgundy | D18: Ordered | E18: 75 | F18: m | G18: 46069
A19: FAB-26W-1038 | B19: 1038-OLV | C19: Olive | D19: Ordered | E19: 60 | F19: m | G19: 46069
A20: FAB-26W-1038 | B20: 1038-GRY | C20: Grey melange | D20: Ordered | E20: 155 | F20: m | G20: 46039
A21: LEA-26W-1040 | B21: 1040-CHK | C21: Chalk | D21: Lab dip | F21: sqft
A22: LEA-26W-1040 | B22: 1040-BRD | C22: Burgundy | D22: Ordered | E22: 540 | F22: sqft | G22: 46040
A23: LEA-26W-1040 | B23: 1040-NVY | C23: Navy | D23: Ordered | E23: 50 | F23: sqft | G23: 46082
A24: LEA-26W-1040 | B24: 1040-WHT | C24: Optic white | D24: Ordered | E24: 500 | F24: sqft | G24: 46060
A25: LEA-26W-1044 | B25: 1044-OLV | C25: Olive | D25: Ordered | E25: 120 | F25: sqft | G25: 46070
A26: LEA-26W-1044 | B26: 1044-TAN | C26: Tan | D26: Ordered | E26: 270 | F26: sqft | G26: 46044
A27: LEA-26W-1044 | B27: 1044-SKY | C27: Sky blue | D27: Cancelled | F27: sqft
A28: LEA-26W-1044 | B28: 1044-GRN | C28: Bottle green | D28: Cancelled | F28: sqft
A29: LEA-26W-1045 | B29: 1045-YLW | C29: Butter yellow | D29: Ordered | E29: 150 | F29: sqft | G29: 46041
A30: LEA-26W-1045 | B30: 1045-CHC | C30: Chocolate | D30: Ordered | E30: 120 | F30: sqft | G30: 46056
A31: LEA-26W-1046 | B31: 1046-GRY | C31: Grey melange | D31: Lab dip | F31: sqft
A32: FAB-26W-1051 | B32: 1051-OLV | C32: Olive | D32: Cancelled | F32: m
A33: LEA-26W-1053 | B33: 1053-WHT | C33: Optic white | D33: Ordered | E33: 510 | F33: sqft | G33: 46052
A34: LEA-26W-1053 | B34: 1053-NVY | C34: Navy | D34: Ordered | E34: 220 | F34: sqft | G34: 46061
A35: LEA-26W-1053 | B35: 1053-CML | C35: Camel | D35: Lab dip | F35: sqft
A36: LEA-26W-1053 | B36: 1053-YLW | C36: Butter yellow | D36: Lab dip | F36: sqft
A37: LEA-26W-1053 | B37: 1053-TRC | C37: Terracotta | D37: Ordered | E37: 110 | F37: sqft | G37: 46064
A38: FAB-26W-1057 | B38: 1057-CML | C38: Camel | D38: Ordered | E38: 165 | F38: m | G38: 46029
A39: FAB-26W-1057 | B39: 1057-GRY | C39: Grey melange | D39: Ordered | E39: 45 | F39: m | G39: 46052
A40: FAB-26W-1057 | B40: 1057-GRN | C40: Bottle green | D40: Cancelled | F40: m
...

Sheet Styles & SKUs
A1: SKU | B1: Style code | C1: Style name | D1: Gender | E1: Collection | F1: Development stage | G1: Main material code | H1: Colour code | I1: Colour name
A2: S26W0104-CHC | B2: S26W0104 | C2: Cape | D2: Men | E2: FW26 | F2: Fitting 2 | G2: FAB-26W-1001 | H2: 1001-CHC | I2: Chocolate
A3: S26W0108-CHC | B3: S26W0108 | C3: Coat | D3: Women | E3: FW26 | F3: Fitting 3 | G3: FAB-26W-1001 | H3: 1001-CHC | I3: Chocolate
A4: S26W0112-CHC | B4: S26W0112 | C4: Puffer | D4: Women | E4: FW26 | F4: Fitting 2 | G4: FAB-26W-1005 | H4: 1005-CHC | I4: Chocolate
A5: S26W0116-ECR | B5: S26W0116 | C5: Chore jacket | D5: Women | E5: FW26 | F5: Fitting 2 | G5: FAB-26W-1010 | H5: 1010-ECR | I5: Ecru
A6: S26W0118-ECR | B6: S26W0118 | C6: Chore jacket | D6: Women | E6: FW26 | F6: Fitting 3 | G6: FAB-26W-1010 | H6: 1010-ECR | I6: Ecru
A7: S26W0120-ECR | B7: S26W0120 | C7: Slip dress | D7: Women | E7: FW26 | F7: Fitting 2 | G7: FAB-26W-1012 | H7: 1012-ECR | I7: Ecru
A8: S26W0120-WHT | B8: S26W0120 | C8: Slip dress | D8: Women | E8: FW26 | F8: Fitting 2 | G8: FAB-26W-1012 | H8: 1012-WHT | I8: Optic white
A9: S26W0122-CHK | B9: S26W0122 | C9: Trousers | D9: Women | E9: FW26 | F9: Fitting 2 | G9: FAB-26W-1019 | H9: 1019-CHK | I9: Chalk
A10: S26W0124-GRY | B10: S26W0124 | C10: Blazer | D10: Women | E10: FW26 | F10: Fitting 1 | G10: FAB-26W-1019 | H10: 1019-GRY | I10: Grey melange
A11: S26W0124-CHK | B11: S26W0124 | C11: Blazer | D11: Women | E11: FW26 | F11: Fitting 1 | G11: FAB-26W-1019 | H11: 1019-CHK | I11: Chalk
A12: S26W0125-SKY | B12: S26W0125 | C12: Shirt dress | D12: Men | E12: FW26 | F12: Fitting 2 | G12: FAB-26W-1024 | H12: 1024-SKY | I12: Sky blue
... A501: S27S0929-GRN | B501: S27S0929 | C501: Cardigan | D501: Women | E501: SS27 | F501: Fitting 1 | G501: YRN-27S-1818 | H501: 1818-GRN | I501: Bottle green

Sheet Summary
A1: Summary (formulas, updates if you edit the data)
A3: 1. Missing data per field
A4: Field | B4: Empty | C4: TBD / n/a | D4: Total missing | E4: % missing
A5: Description | B5: =COUNTBLANK(Materials!$B$2:$B$221) -> 3 | C5: =COUNTIF(Materials!$B$2:$B$221,"TBD")+COUNTIF(Materials!$B$2:$B$221,"n/a") -> 0 | D5: =B5+C5 -> 3 | E5: =D5/$B$16 -> 0.013636364
A6: Composition | B6: =COUNTBLANK(Materials!$G$2:$G$221) -> 7 | C6: =COUNTIF(Materials!$G$2:$G$221,"TBD")+COUNTIF(Materials!$G$2:$G$221,"n/a") -> 0 | D6: =B6+C6 -> 7 | E6: =D6/$B$16 -> 0.031818182
A7: Weight | B7: =COUNTBLANK(Materials!$H$2:$H$221) -> 24 | C7: =COUNTIF(Materials!$H$2:$H$221,"TBD")+COUNTIF(Materials!$H$2:$H$221,"n/a") -> 0 | D7: =B7+C7 -> 24 | E7: =D7/$B$16 -> 0.10909091
A8: Width / skin size | B8: =COUNTBLANK(Materials!$I$2:$I$221) -> 20 | C8: =COUNTIF(Materials!$I$2:$I$221,"TBD")+COUNTIF(Materials!$I$2:$I$221,"n/a") -> 0 | D8: =B8+C8 -> 20 | E8: =D8/$B$16 -> 0.090909091
A9: Price | B9: =COUNTBLANK(Materials!$J$2:$J$221) -> 37 | C9: =COUNTIF(Materials!$J$2:$J$221,"TBD")+COUNTIF(Materials!$J$2:$J$221,"n/a") -> 24 | D9: =B9+C9 -> 61 | E9: =D9/$B$16 -> 0.27727273
A10: Price unit | B10: =COUNTBLANK(Materials!$L$2:$L$221) -> 6 | C10: =COUNTIF(Materials!$L$2:$L$221,"TBD")+COUNTIF(Materials!$L$2:$L$221,"n/a") -> 0 | D10: =B10+C10 -> 6 | E10: =D10/$B$16 -> 0.027272727
A11: MOQ | B11: =COUNTBLANK(Materials!$M$2:$M$221) -> 20 | C11: =COUNTIF(Materials!$M$2:$M$221,"TBD")+COUNTIF(Materials!$M$2:$M$221,"n/a") -> 15 | D11: =B11+C11 -> 35 | E11: =D11/$B$16 -> 0.15909091
A12: Lead time (wks) | B12: =COUNTBLANK(Materials!$N$2:$N$221) -> 33 | C12: =COUNTIF(Materials!$N$2:$N$221,"TBD")+COUNTIF(Materials!$N$2:$N$221,"n/a") -> 18 | D12: =B12+C12 -> 51 | E12: =D12/$B$16 -> 0.23181818
A13: Country of origin | B13: =COUNTBLANK(Materials!$O$2:$O$221) -> 12 | C13: =COUNTIF(Materials!$O$2:$O$221,"TBD")+COUNTIF(Materials!$O$2:$O$221,"n/a") -> 0 | D13: =B13+C13 -> 12 | E13: =D13/$B$16 -> 0.054545455
A14: Certification | B14: =COUNTBLANK(Materials!$P$2:$P$221) -> 50 | C14: =COUNTIF(Materials!$P$2:$P$221,"TBD")+COUNTIF(Materials!$P$2:$P$221,"n/a") -> 0 | D14: =B14+C14 -> 50 | E14: =D14/$B$16 -> 0.22727273
A16: Materials in export | B16: =COUNTA(Materials!$A$2:$A$221) -> 220
A19: 2. SKUs per development stage
A20: Stage | B20: FW26 | C20: Pre-SS27 | D20: SS27 | E20: Total
A21: Edit | B21: =COUNTIFS('Styles & SKUs'!$F$2:$F$501,$A21,'Styles & SKUs'!$E$2:$E$501,B$20) -> 15 | C21: =COUNTIFS('Styles & SKUs'!$F$2:$F$501,$A21,'Styles & SKUs'!$E$2:$E$501,C$20) -> 25 | D21: =COUNTIFS('Styles & SKUs'!$F$2:$F$501,$A21,'Styles & SKUs'!$E$2:$E$501,D$20) -> 41 | E21: =SUM(B21:D21) -> 81
A22: Fitting 1 | B22: =COUNTIFS('Styles & SKUs'!$F$2:$F$501,$A22,'Styles & SKUs'!$E$2:$E$501,B$20) -> 41 | C22: =COUNTIFS('Styles & SKUs'!$F$2:$F$501,$A22,'Styles & SKUs'!$E$2:$E$501,C$20) -> 28 | D22: =COUNTIFS('Styles & SKUs'!$F$2:$F$501,$A22,'Styles & SKUs'!$E$2:$E$501,D$20) -> 67 | E22: =SUM(B22:D22) -> 136
A23: Fitting 2 | B23: =COUNTIFS('Styles & SKUs'!$F$2:$F$501,$A23,'Styles & SKUs'!$E$2:$E$501,B$20) -> 38 | C23: =COUNTIFS('Styles & SKUs'!$F$2:$F$501,$A23,'Styles & SKUs'!$E$2:$E$501,C$20) -> 51 | D23: =COUNTIFS('Styles & SKUs'!$F$2:$F$501,$A23,'Styles & SKUs'!$E$2:$E$501,D$20) -> 67 | E23: =SUM(B23:D23) -> 156
A24: Fitting 3 | B24: =COUNTIFS('Styles & SKUs'!$F$2:$F$501,$A24,'Styles & SKUs'!$E$2:$E$501,B$20) -> 12 | C24: =COUNTIFS('Styles & SKUs'!$F$2:$F$501,$A24,'Styles & SKUs'!$E$2:$E$501,C$20) -> 14 | D24: =COUNTIFS('Styles & SKUs'!$F$2:$F$501,$A24,'Styles & SKUs'!$E$2:$E$501,D$20) -> 34 | E24: =SUM(B24:D24) -> 60
A25: Dropped | B25: =COUNTIFS('Styles & SKUs'!$F$2:$F$501,$A25,'Styles & SKUs'!$E$2:$E$501,B$20) -> 12 | C25: =COUNTIFS('Styles & SKUs'!$F$2:$F$501,$A25,'Styles & SKUs'!$E$2:$E$501,C$20) -> 12 | D25: =COUNTIFS('Styles & SKUs'!$F$2:$F$501,$A25,'Styles & SKUs'!$E$2:$E$501,D$20) -> 43 | E25: =SUM(B25:D25) -> 67
A26: Total SKUs | B26: =SUM(B21:B25) -> 118 | C26: =SUM(C21:C25) -> 130 | D26: =SUM(D21:D25) -> 252 | E26: =SUM(E21:E25) -> 500
A29: 3. Colours ordered per fabric
A30: Colours ordered | B30: Materials | C30: % of materials
A31: 0 | B31: =COUNTIFS(Materials!$V$2:$V$221,">=0",Materials!$V$2:$V$221,"<=0") -> 22 | C31: =B31/SUM($B$31:$B$35) -> 0.1
A32: 1 | B32: =COUNTIFS(Materials!$V$2:$V$221,">=1",Materials!$V$2:$V$221,"<=1") -> 72 | C32: =B32/SUM($B$31:$B$35) -> 0.32727273
A33: 2 | B33: =COUNTIFS(Materials!$V$2:$V$221,">=2",Materials!$V$2:$V$221,"<=2") -> 48 | C33: =B33/SUM($B$31:$B$35) -> 0.21818182
A34: 3–4 | B34: =COUNTIFS(Materials!$V$2:$V$221,">=3",Materials!$V$2:$V$221,"<=4") -> 66 | C34: =B34/SUM($B$31:$B$35) -> 0.3
A35: 5 or more | B35: =COUNTIFS(Materials!$V$2:$V$221,">=5",Materials!$V$2:$V$221,"<=99") -> 12 | C35: =B35/SUM($B$31:$B$35) -> 0.054545455
A36: Avg colours ordered per material | B36: =AVERAGE(Materials!$V$2:$V$221) -> 2.0545455
A37: Counts colours with status "Ordered" (column "Colours ordered (calc)" on the Materials sheet).

Sheet Read me
A1: SAMPLE PLM DATA – INVENTED
A3: What this is | B3: Fake data shaped like a PLM material export, for testing the prototypes. Every supplier, code, price and quantity is invented. Nothing comes from Loewe systems.
A4: Materials | B4: 220 materials across FW26, Pre-SS27 and SS27. Some fields are left empty, "TBD" or "n/a" on purpose (most often Price, Lead time, Certification and MOQ). Empty cells are highlighted in pink. Keep this as the first sheet: PLM Data Health reads the first sheet of the file.
A5: Colours | B5: 741 colour lines linked to materials by Material code. Status is Ordered, Lab dip or Cancelled; quantity only for Ordered colours.
A6: Styles & SKUs | B6: 500 SKUs (style + colour) with their development stage (Edit, Fitting 1, Fitting 2, Fitting 3, Dropped), linked to the main material and colour codes.
A7: Summary | B7: Formulas that recalculate: % missing per field, SKUs per stage and collection, and colours ordered per fabric.
A8: Composition codes | B8: Textile codes as used on labels: WV wool, WM mohair, WS cashmere, WO wool, CO cotton, SE silk, CV viscose, LI linen, PA polyamide, PES polyester, EA elastane, PU polyurethane.
A9: How to use it | B9: Open PLM Data Health, click "Load PLM export" and pick this file. Comments is often empty on purpose, so the tool skips it by default (turn it back on under "Columns checked").
